<?xml version="1.0"?>
<robot xmlns:xacro="http://www.ros.org/wiki/xacro">

  <xacro:include filename="$(find schunk_description)/urdf/pw70/pw70.gazebo.xacro" />
  <xacro:include filename="$(find schunk_description)/urdf/pw70/pw70.transmission.xacro" />

  <xacro:macro name="schunk_pw70" params="parent name *origin">

    <joint name="${name}_base_joint" type="fixed" >
      <parent link="${parent}" />
      <child link="${name}_base_link" />
      <xacro:insert_block name="origin" />
    </joint>

    <link name="${name}_base_link">
      <xacro:default_inertial/>
	  <!--
      <visual>
        <geometry>
          <mesh filename="package://schunk_description/meshes/pw70/pw70_base.dae" />
        </geometry>
      </visual>
      <collision>
        <geometry>
          <mesh filename="package://schunk_description/meshes/pw70/pw70_base.stl" />
        </geometry>
      </collision>
	  -->
    </link>

    <joint name="${name}_pan_joint" type="revolute" >
      <origin xyz="0 0 0" rpy="0 0 0"/>
      <parent link="${name}_base_link" />
      <child link="${name}_pan_link" />
      <axis xyz="0 0 1" />
	  <!--<limit effort="10" lower="-0.001" upper="0.061" velocity="2.0"/>-->
    </joint>

    <link name="${name}_pan_link">
      <xacro:default_inertial/>
      <!--
      <visual>
        <geometry>
          <mesh filename="package://schunk_description/meshes/pw70/pw70_pan.dae" />
        </geometry>
      </visual>
      <collision>
        <geometry>
          <mesh filename="package://schunk_description/meshes/pw70/pw70_pan.stl" />
        </geometry>
      </collision>
	  -->
    </link>


    <joint name="${name}_tilt_joint" type="revolute" >
      <origin xyz="0 0 0" rpy="0 0 0"/>
      <parent link="${name}_pan_link" />
      <child link="${name}_tilt_link" />
      <axis xyz="0 1 0" />
	  <!--<mimic joint="${name}_finger_left_joint" multiplier="1" offset="0"/>
	  <limit effort="10" lower="-0.001" upper="0.061" velocity="2.0"/>-->
    </joint>

    <link name="${name}_tilt_link">
      <xacro:default_inertial/>
	  <!--
      <visual>
        <geometry>
          <mesh filename="package://schunk_description/meshes/pw70/pw70_tilt.dae" />
        </geometry>
      </visual>
      <collision>
        <geometry>
          <mesh filename="package://schunk_description/meshes/pw70/pw70_tilt.stl" />
        </geometry>
      </collision>
	  -->
    </link>

	<joint name="${name}_tool_joint" type="fixed" >
	  <origin xyz="0 0 0" rpy="0 0 0"/>
      <parent link="${name}_tilt_joint" />
      <child link="${name}_tool_link" />
      <xacro:insert_block name="origin" />
    </joint>

  <!-- extensions -->
  <xacro:schunk_pw70_gazebo name="${name}" />
  <xacro:schunk_pw70_transmission name="${name}" />


  </xacro:macro>
</robot>

