<?xml version="1.0"?>
<robot xmlns:sensor="http://playerstage.sourceforge.net/gazebo/xmlschema/#sensor"
       xmlns:controller="http://playerstage.sourceforge.net/gazebo/xmlschema/#controller"
       xmlns:interface="http://playerstage.sourceforge.net/gazebo/xmlschema/#interface"
       xmlns:xacro="http://ros.org/wiki/xacro">

	<include filename="$(find schunk_description)/urdf/lwa4d/lwa4d.gazebo.xacro" />
	<include filename="$(find schunk_description)/urdf/lwa4d/lwa4d.transmission.xacro" />

	<xacro:macro name="schunk_lwa4d" params="parent name *origin">

		<!-- joint between base_link and arm_0_link -->
		<joint name="${name}_0_joint" type="fixed" >
			<insert_block name="origin" />
			<parent link="${parent}" />
			<child link="${name}_0_link" />
		</joint>

		<link name="${name}_0_link">
			<inertial>
				<origin xyz="0 0 0" rpy="0 0 0"/>
				<mass value="1.0"/>
				<inertia ixx="0.01" ixy="0" ixz="0" iyy="0.01" iyz="0" izz="0.01" />
			</inertial>

			<visual>
				<origin xyz="0 0 0.004" rpy="0 0 0" />
				<geometry>
					<cylinder radius="0.045" length="0.08"/>
				</geometry>
				<material name="Schunk/Black" />
			</visual>
n
			<collision>
				<origin xyz="0 0 0.005" rpy="0 0 0" />
				<geometry>
					<box size="0.01 0.01 0.01"/>
				</geometry>
			</collision>
		</link>

		<!-- joint between arm_0_link and arm_1_link -->
		<joint name="${name}_1_joint" type="revolute">
			<origin xyz="0 0 0.15" rpy="0 -${M_PI} 0"/>
			<parent link="${name}_0_link"/>
			<child link="${name}_1_link"/>
			<axis xyz="0 0 1"/>
			<calibration rising="${arm_1_ref}"/>
			<dynamics damping="10" />
			<limit effort="370" velocity="2.0" lower="-6.2831853" upper="6.2831853"/>
			<safety_controller k_position="20" k_velocity="50" soft_lower_limit="${-6.2831853 + 0.01}" soft_upper_limit="${6.2831853 - 0.01}" />
		</joint>

		<link name="${name}_1_link">
			<inertial>
				<origin xyz="0 0 0" rpy="0 0 0" />
				<!--mass value="5.9907"/-->
				<mass value="2.0"/>
				<inertia ixx="0.01" ixy="0" ixz="0" iyy="0.01" iyz="0" izz="0.01" />
			</inertial>
			
			<visual>
				<origin xyz="0 0 -0.15" rpy="0 0 ${M_PI}" />
				<geometry>
					<mesh filename="package://schunk_description/meshes/lwa4d/arm_1_link.stl" />
				</geometry>
				<material name="Schunk/LightGrey" />
			</visual>
			
			<collision>
				<origin xyz="0 0 -0.15" rpy="0 0 ${M_PI}" />
				<geometry>
					<mesh filename="package://schunk_description/meshes/lwa4d/arm_1_link.stl" />
				</geometry>
			</collision>
		</link>

		<!-- joint between arm_1_link and arm_2_link -->	
		<joint name="${name}_2_joint" type="revolute">
			<origin xyz="0 0 -0.15" rpy="-${M_PI/2} 0 0"/>
			<parent link="${name}_1_link"/>
			<child link="${name}_2_link"/>
			<axis xyz="0 0 1"/>
			<calibration rising="${arm_2_ref}"/>
			<dynamics damping="10" />
			<limit effort="370" velocity="2.0" lower="-1.97" upper="1.97"/>
			<safety_controller k_position="20" k_velocity="50" soft_lower_limit="${-1.97 + 0.01}" 	soft_upper_limit="${1.97 - 0.01}" />
		</joint>

		<link name="${name}_2_link">
			<inertial>
				<origin xyz="0 0 0" rpy="0 0 0"/>
				<mass value="2.0"/>
				<inertia ixx="0.03" ixy="0" ixz="0" iyy="0.03" iyz="0" izz="0.03" />
			</inertial>
			
			<visual>
				<origin xyz="0 0 0" rpy="0 0 ${M_PI}" />
				<geometry>
					<mesh filename="package://schunk_description/meshes/lwa4d/arm_2_link.stl" />
				</geometry>
				<material name="Schunk/Black" />
			</visual>
			
			<collision>
				<origin xyz="0 0 0" rpy="0 0 ${M_PI}" />
				<geometry>
					<mesh filename="package://schunk_description/meshes/lwa4d/arm_2_link.stl"/>
				</geometry>
			</collision>
		</link>

		<!-- joint between arm_2_link and arm_3_link -->	
		<joint name="${name}_3_joint" type="revolute">
			<origin xyz="0 0 0" rpy="${M_PI/2} 0 0"/>
			<parent link="${name}_2_link"/>
			<child link="${name}_3_link"/>
			<axis xyz="0 0 1"/>
			<calibration rising="${arm_3_ref}"/>
			<dynamics damping="5" />
			<limit effort="176" velocity="2.0" lower="-6.2831853" upper="6.2831853"/>
			<safety_controller k_position="20" k_velocity="25" soft_lower_limit="${-6.2831853 + 0.01}" soft_upper_limit="${6.2831853 - 0.01}" />
		</joint>

		<link name="${name}_3_link">
			<inertial>
				<origin xyz="0 0 0" rpy="0 0 0"/>
				<mass value="2.0"/>
				<inertia ixx="0.03" ixy="0" ixz="0" iyy="0.03" iyz="0" izz="0.03" />
			</inertial>
			
			<visual>
				<origin xyz="0 0 -0.328" rpy="0 0 ${M_PI}" />
				<geometry>
					<mesh filename="package://schunk_description/meshes/lwa4d/arm_3_link.stl" />
				</geometry>
				<material name="Schunk/LightGrey" />
			</visual>
			
			<collision>
				<origin xyz="0 0 -0.328" rpy="0 0 ${M_PI}" />
				<geometry>
					<mesh filename="package://schunk_description/meshes/lwa4d/arm_3_link.stl"/>
				</geometry>
			</collision>
		</link>	

		<!-- joint between arm_3_link and arm_4_link -->
		<joint name="${name}_4_joint" type="revolute">
			<origin xyz="0 0 -0.328" rpy="-${M_PI/2} 0 0"/>
			<parent link="${name}_3_link"/>
			<child link="${name}_4_link"/>
			<axis xyz="0 0 1" />
			<calibration rising="${arm_4_ref}"/>
			<dynamics damping="5" />
			<limit effort="176" velocity="2.0" lower="-2.08208" upper="2.08208"/>
			<safety_controller k_position="20" k_velocity="25" soft_lower_limit="${-2.08208 + 0.01}" soft_upper_limit="${2.08208 - 0.01}" />
		</joint>

		<link name="${name}_4_link">
			<inertial>
				<origin xyz="0 0 0" rpy="0 0 0"/>
				<mass value="2.0"/>
				<inertia ixx="0.03" ixy="0" ixz="0" iyy="0.03" iyz="0" izz="0.03" />
			</inertial>
			
			<visual>
				<origin xyz="0 0 0" rpy="0 0 ${M_PI}" />
				<geometry>
					<mesh filename="package://schunk_description/meshes/lwa4d/arm_4_link.stl" />
				</geometry>
				<material name="Schunk/Black" />
			</visual>
			
			<collision>
				<origin xyz="0 0 0" rpy="0 0 ${M_PI}" />
				<geometry>
					<mesh filename="package://schunk_description/meshes/lwa4d/arm_4_link.stl"/>
				</geometry>
			</collision>
		</link>

		<!-- joint between arm_4_link and arm_5_link -->
		<joint name="${name}_5_joint" type="revolute">
			<origin xyz="0 0 0" rpy="${M_PI/2} 0 0" />
			<parent link="${name}_4_link"/>
			<child link="${name}_5_link"/>
			<axis xyz="0 0 1" />
			<calibration rising="${arm_5_ref}"/>
			<dynamics damping="5" />
			<limit effort="41.6" velocity="2.0" lower="-6.2831853" upper="6.2831853" />
			<safety_controller k_position="20" k_velocity="25" soft_lower_limit="${-6.2831853 + 0.01}" soft_upper_limit="${6.2831853 - 0.01}" />
		</joint>

		<link name="${name}_5_link">
			<inertial>
				<origin xyz="0 0 0" rpy="0 0 0"/>
				<mass value="2.313272"/>
				<inertia ixx="0.03" ixy="0" ixz="0" iyy="0.03" iyz="0" izz="0.03" />
			</inertial>
			
			<visual>
				<origin xyz="0 0 -0.323" rpy="0 0 ${M_PI}" />
				<geometry>
					<mesh filename="package://schunk_description/meshes/lwa4d/arm_5_link.stl" />
				</geometry>
				<material name="Schunk/LightGrey" />
			</visual>
			
			<collision>
				<origin xyz="0 0 -0.323" rpy="0 0 ${M_PI}" />
				<geometry>
					<mesh filename="package://schunk_description/meshes/lwa4d/arm_5_link.stl"/>
				</geometry>
			</collision>
		</link>

		<!-- joint between arm_5_link and arm_6_link -->
		<joint name="${name}_6_joint" type="revolute">
			<origin xyz="0 0 -0.323" rpy="${M_PI/2} 0 0" />
			<parent link="${name}_5_link"/>
			<child link="${name}_6_link"/>
			<axis xyz="0 0 1" />
			<calibration rising="${arm_6_ref}"/>
			<dynamics damping="5" />
			<limit effort="20.1" velocity="2.0" lower="-1.8" upper="1.8" />
			<safety_controller k_position="20" k_velocity="25" soft_lower_limit="${-1.8 + 0.01}" soft_upper_limit="${1.8 - 0.01}" />
		</joint>

		<link name="${name}_6_link">
			<inertial>
				<origin xyz="0 0 0" rpy="0 0 0"/>
				<mass value="2.057856"/>
				<inertia ixx="0.01" ixy="0" ixz="0" iyy="0.01" iyz="0" izz="0.01" />
			</inertial>
			
			<visual>
				<origin xyz="0 0 0" rpy="0 0 ${M_PI}" />
				<geometry>
					<mesh filename="package://schunk_description/meshes/lwa4d/arm_6_link.stl" />
				</geometry>
				<material name="Schunk/Black" />
			</visual>
			
			<collision>
				<origin xyz="0 0 0" rpy="0 0 ${M_PI}" />
				<geometry>
					<mesh filename="package://schunk_description/meshes/lwa4d/arm_6_link.stl"/>
				</geometry>
			</collision>
		</link>

		<!-- joint between arm_6_link and arm_7_link -->
		<joint name="${name}_7_joint" type="revolute">
			<origin xyz="0 -0.075 0" rpy="${M_PI/2} 0 0" />
			<parent link="${name}_6_link"/>
			<child link="${name}_7_link"/>
			<axis xyz="0 0 1" />
			<calibration rising="${arm_7_ref}"/>
			<dynamics damping="5" />
			<limit effort="9.6" velocity="2.0" lower="-6.2831853" upper="6.2831853" />
			<safety_controller k_position="20" k_velocity="25" soft_lower_limit="${-6.2831853 + 0.01}" soft_upper_limit="${6.2831853 - 0.01}" />
		</joint>

		<link name="${name}_7_link">
			<inertial>
				<origin xyz="0 0 0" rpy="0 0 0"/>
				<mass value="1.120198"/>
				<inertia ixx="0.01" ixy="0" ixz="0" iyy="0.01" iyz="0" izz="0.01" />
			</inertial>
			
			<visual>
				<origin xyz="0 0 -0.075" rpy="0 0 0" />
				<geometry>
					<mesh filename="package://schunk_description/meshes/lwa4d/arm_7_link.stl" />
				</geometry>
				<material name="Schunk/LightGrey" />
			</visual>
			
			<collision>
				<origin xyz="0 0 -0.075" rpy="0 0 0" />
				<geometry>
					<mesh filename="package://schunk_description/meshes/lwa4d/arm_7_link.stl"/>
				</geometry>
			</collision>
		</link>

		<!-- extensions -->
		<xacro:schunk_lwa4d_gazebo name="${name}" />
		<xacro:schunk_lwa4d_transmission name="${name}" />

	</xacro:macro>

</robot>
