<?xml version="1.0"?>
<robot xmlns:xacro="http://www.ros.org/wiki/xacro">

  <xacro:include filename="$(find schunk_description)/urdf/common.xacro" />
  <xacro:include filename="$(find schunk_description)/urdf/lwa/lwa.gazebo.xacro" />
  <xacro:include filename="$(find schunk_description)/urdf/lwa/lwa.transmission.xacro" />

  <xacro:macro name="schunk_lwa" params="parent name *origin">

    <!-- joint between base_link and arm_0_link -->
    <joint name="${name}_base_joint" type="fixed" >
      <xacro:insert_block name="origin" />
      <parent link="${parent}" />
      <child link="${name}_base_link" />
    </joint>

    <link name="${name}_base_link">
      <xacro:default_inertial/>
      <visual>
        <origin xyz="0 0 0.004" rpy="0 0 0" />
        <geometry>
          <cylinder radius="0.045" length="0.08"/>
        </geometry>
        <material name="Schunk/DarkGolden" />
      </visual>
      <collision>
        <origin xyz="0 0 0.005" rpy="0 0 0" />
        <geometry>
          <box size="0.01 0.01 0.01"/>
        </geometry>
      </collision>
    </link>

    <!-- joint between arm_0_link and arm_1_link -->
    <joint name="${name}_1_joint" type="revolute">
      <origin xyz="0 0 -0.250" rpy="0 0 3.1415926"/>
      <parent link="${name}_base_link"/>
      <child link="${name}_1_link"/>
      <axis xyz="0 0 1"/>
      <dynamics damping="10" />
      <limit effort="370" velocity="2.0" lower="-3.1415" upper="3.1415"/>
      <!--limit effort="370" velocity="2.0" lower="-6.25" upper="6.25"/-->
      <!--safety_controller k_position="20" k_velocity="50" soft_lower_limit="${-6.25 + 0.01}" soft_upper_limit="${6.25 - 0.01}" /-->
    </joint>

    <link name="${name}_1_link">
      <xacro:default_inertial/>
      <visual>
        <origin xyz="0 0 0" rpy="0 0 0" />
        <geometry>
          <mesh filename="package://schunk_description/meshes/lwa/lwa1.stl" />
        </geometry>
        <material name="Schunk/DarkGolden" />
      </visual>
      <collision>
        <origin xyz="0 0 0" rpy="0 0 0" />
        <geometry>
          <mesh filename="package://schunk_description/meshes/lwa/lwa1.stl" />
        </geometry>
      </collision>
    </link>

    <!-- joint between arm_1_link and arm_2_link -->
    <joint name="${name}_2_joint" type="revolute">
      <origin xyz="0 0 0" rpy="1.5708 0 0"/>
      <parent link="${name}_1_link"/>
      <child link="${name}_2_link"/>
      <axis xyz="0 0 1"/>
      <dynamics damping="10" />
      <limit effort="370" velocity="2.0" lower="-1.97" upper="1.97"/>
      <!--safety_controller k_position="20" k_velocity="50" soft_lower_limit="${-1.97 + 0.01}"   soft_upper_limit="${1.97 - 0.01}" /-->
    </joint>

    <link name="${name}_2_link">
      <xacro:default_inertial/>
      <visual>
        <origin xyz="0 0 0" rpy="0 0 0" />
        <geometry>
          <mesh filename="package://schunk_description/meshes/lwa/lwa2.stl" />
        </geometry>
        <material name="Schunk/DarkGolden" />
      </visual>
      <collision>
        <origin xyz="0 0 0" rpy="0 0 0" />
        <geometry>
          <mesh filename="package://schunk_description/meshes/lwa/lwa2.stl"/>
        </geometry>
      </collision>
    </link>

    <!-- joint between arm_2_link and arm_3_link -->
    <joint name="${name}_3_joint" type="revolute">
      <origin xyz="0 -0.408 0" rpy="-1.5708 0 0"/>
      <parent link="${name}_2_link"/>
      <child link="${name}_3_link"/>
      <axis xyz="0 0 1"/>
      <dynamics damping="5" />
      <limit effort="176" velocity="2.0" lower="-3.1415" upper="3.1415"/>
      <!--limit effort="176" velocity="2.0" lower="-6.25" upper="6.25"/-->
      <!--safety_controller k_position="20" k_velocity="25" soft_lower_limit="${-6.25 + 0.01}" soft_upper_limit="${6.25 - 0.01}" /-->
    </joint>

    <link name="${name}_3_link">
      <xacro:default_inertial/>
      <visual>
        <origin xyz="0 0 0" rpy="0 0 0" />
        <geometry>
          <mesh filename="package://schunk_description/meshes/lwa/lwa3.stl" />
        </geometry>
        <material name="Schunk/DarkGolden" />
      </visual>
      <collision>
        <origin xyz="0 0 0" rpy="0 0 0" />
        <geometry>
          <mesh filename="package://schunk_description/meshes/lwa/lwa3.stl"/>
        </geometry>
      </collision>
    </link>

    <!-- joint between arm_3_link and arm_4_link -->
    <joint name="${name}_4_joint" type="revolute">
      <origin xyz="0 0 0" rpy="1.5708 0 0" />
      <parent link="${name}_3_link"/>
      <child link="${name}_4_link"/>
      <axis xyz="0 0 1" />
      <dynamics damping="5" />
      <limit effort="176" velocity="2.0" lower="-1.97" upper="1.97"/>
      <!--safety_controller k_position="20" k_velocity="25" soft_lower_limit="${-1.97 + 0.01}" soft_upper_limit="${1.97 - 0.01}" /-->
    </joint>

    <link name="${name}_4_link">
      <xacro:default_inertial/>
      <visual>
        <origin xyz="0 0 0" rpy="0 0 0" />
        <geometry>
          <mesh filename="package://schunk_description/meshes/lwa/lwa4.stl" />
        </geometry>
        <material name="Schunk/DarkGolden" />
      </visual>
      <collision>
        <origin xyz="0 0 0" rpy="0 0 0" />
        <geometry>
          <mesh filename="package://schunk_description/meshes/lwa/lwa4.stl"/>
        </geometry>
      </collision>
    </link>

    <!-- joint between arm_4_link and arm_5_link -->
    <joint name="${name}_5_joint" type="revolute">
      <origin xyz="0 -0.3165 0" rpy="-1.5708 0 0" />
      <parent link="${name}_4_link"/>
      <child link="${name}_5_link"/>
      <axis xyz="0 0 1" />
      <dynamics damping="5" />
      <limit effort="41.6" velocity="2.0" lower="-3.1415" upper="3.1415" />
      <!--limit effort="41.6" velocity="2.0" lower="-6.25" upper="6.25" /-->
      <!--safety_controller k_position="20" k_velocity="25" soft_lower_limit="${-6.25 + 0.01}" soft_upper_limit="${6.25 - 0.01}" /-->
    </joint>

    <link name="${name}_5_link">
      <xacro:default_inertial/>
      <visual>
        <origin xyz="0 0 0" rpy="0 0 0" />
        <geometry>
          <mesh filename="package://schunk_description/meshes/lwa/lwa5.stl" />
        </geometry>
        <material name="Schunk/DarkGolden" />
      </visual>
      <collision>
        <origin xyz="0 0 0" rpy="0 0 0" />
        <geometry>
          <mesh filename="package://schunk_description/meshes/lwa/lwa5.stl"/>
        </geometry>
      </collision>
    </link>

    <!-- joint between arm_5_link and arm_6_link -->
    <joint name="${name}_6_joint" type="revolute">
      <origin xyz="0 0 0" rpy="1.5708 0 0" />
      <parent link="${name}_5_link"/>
      <child link="${name}_6_link"/>
      <axis xyz="0 0 1" />
      <dynamics damping="5" />
      <limit effort="20.1" velocity="2.0" lower="-1.97" upper="1.97" />
      <!--safety_controller k_position="20" k_velocity="25" soft_lower_limit="${-1.97 + 0.01}" soft_upper_limit="${1.97 - 0.01}" /-->
    </joint>

    <link name="${name}_6_link">
      <xacro:default_inertial/>
      <visual>
        <origin xyz="0 0 0" rpy="0 0 0" />
        <geometry>
          <mesh filename="package://schunk_description/meshes/lwa/lwa6.stl" />
        </geometry>
        <material name="Schunk/DarkGolden" />
      </visual>
      <collision>
        <origin xyz="0 0 0" rpy="0 0 0" />
        <geometry>
          <mesh filename="package://schunk_description/meshes/lwa/lwa6.stl"/>
        </geometry>
      </collision>
    </link>

    <!-- joint between arm_6_link and arm_7_link -->
    <joint name="${name}_7_joint" type="revolute">
      <origin xyz="0 -0.1927 0" rpy="-1.5708 0 0" />
      <parent link="${name}_6_link"/>
      <child link="${name}_7_link"/>
      <axis xyz="0 0 1" />
      <dynamics damping="5" />
      <limit effort="9.6" velocity="2.0" lower="-3.1415" upper="3.1415" />
      <!--limit effort="9.6" velocity="2.0" lower="-6.25" upper="6.25" /-->
      <!--safety_controller k_position="20" k_velocity="25" soft_lower_limit="${-6.25 + 0.01}" soft_upper_limit="${6.25 - 0.01}" /-->
    </joint>

    <link name="${name}_7_link">
      <xacro:default_inertial/>
      <visual>
        <origin xyz="0 0 0" rpy="0 0 0" />
        <geometry>
          <mesh filename="package://schunk_description/meshes/lwa/lwa7.stl" />
        </geometry>
        <material name="Schunk/DarkGolden" />
      </visual>
      <collision>
        <origin xyz="0 0 0" rpy="0 0 0" />
        <geometry>
          <mesh filename="package://schunk_description/meshes/lwa/lwa7.stl"/>
        </geometry>
      </collision>
    </link>

    <!-- extensions -->
    <xacro:schunk_lwa_gazebo name="${name}" />
    <xacro:schunk_lwa_transmission name="${name}" />

    <!-- ros_control plugin -->
    <gazebo>
      <plugin name="ros_control" filename="libhwi_switch_gazebo_ros_control.so">
        <robotNamespace>${name}</robotNamespace>
        <filterJointsParam>joint_names</filterJointsParam>
      </plugin>
    </gazebo>

  </xacro:macro>

</robot>
